Workbook

Sheet Gráfico1

Sheet CORTES
B1: Jueves 1 de enero de 2026 | O1: Domingo 1 de febrero de 2026 | AB1: Domingo 1 de marzo de 2026 | AO1: Miércoles 1 de abril de 2026 | BB1: Viernes 1 de mayo de 2025 | BP1: Lunes 1 de junio de 2026 | CC1: Miércoles 1 de julio de 2026 | CP1: Sábado 1 de agosto de 2026 | DC1: Martes 1 de septiembre de 2026 | DP1: Jueves 1 de octubre de 2026 | EC1: Domingo 1 de noviembre de 2026 | EP1: Martes 1 de diciembre de 2026
B3: Caja | C3: EFECTIVO | E3: TARJETA | G3: Gastos | J3: Ventas Totales | L3: =C48+E48 -> 21240 | O3: Caja | P3: EFECTIVO | R3: TARJETA | T3: Gastos | W3: Ventas Totales | Y3: =P41+R41 -> 11905 | AB3: Caja | AC3: EFECTIVO | AE3: TARJETA | AG3: Gastos | AJ3: Ventas Totales | AL3: =AC29+AE29 -> 6411 | AO3: Caja | AP3: EFECTIVO | AR3: TARJETA | AT3: Gastos | AW3: Ventas Totales | AY3: =AP21+AR21 -> 4396 | BB3: Caja | BC3: EFECTIVO | BE3: TARJETA | BG3: Gastos | BJ3: Ventas Totales | BL3: =BC21+BE21 -> 6137 | BP3: Caja | BQ3: EFECTIVO | BS3: TARJETA | BU3: Gastos | BX3: Ventas Totales | BZ3: =BQ42+BS42 -> 0 | CC3: Caja | CD3: EFECTIVO | CF3: TARJETA | CH3: Gastos | CK3: Ventas Totales | CM3: =CD42+CF42 -> 0 | CP3: Caja | CQ3: EFECTIVO | CS3: TARJETA | CU3: Gastos | CX3: Ventas Totales | CZ3: =CQ42+CS42 -> 0 | DC3: Caja | DD3: EFECTIVO | DF3: TARJETA | DH3: Gastos | DK3: Ventas Totales | DM3: =DD42+DF42 -> 0 | DP3: Caja | DQ3: EFECTIVO | DS3: TARJETA | DU3: Gastos | DX3: Ventas Totales | DZ3: =DQ42+DS42 -> 0 | EC3: Caja | ED3: EFECTIVO | EF3: TARJETA | EH3: Gastos | EK3: Ventas Totales | EM3: =ED42+EF42 -> 0 | EP3: Caja | EQ3: EFECTIVO | ES3: TARJETA | EU3: Gastos | EX3: Ventas Totales | EZ3: =EQ42+ES42 -> 0
C4: Venta | D4: Propinas | E4: Venta | F4: Propinas | J4: Propinas Totales | L4: =D48+F48 -> 1873.35 | P4: Venta | Q4: Propinas | R4: Venta | S4: Propinas | W4: Propinas Totales | Y4: =Q41+S41 -> 1209.5 | AC4: Venta | AD4: Propinas | AE4: Venta | AF4: Propinas | AJ4: Propinas Totales | AL4: =AD29+AF29 -> 674.95 | AP4: Venta | AQ4: Propinas | AR4: Venta | AS4: Propinas | AW4: Propinas Totales | AY4: =AQ21+AS21 -> 508.5 | BC4: Venta | BD4: Propinas | BE4: Venta | BF4: Propinas | BJ4: Propinas Totales | BL4: =BD21+BF21 -> 534.6 | BQ4: Venta | BR4: Propinas | BS4: Venta | BT4: Propinas | BX4: Propinas Totales | BZ4: =BR42+BT42 -> 0 | CD4: Venta | CE4: Propinas | CF4: Venta | CG4: Propinas | CK4: Propinas Totales | CM4: =CE42+CG42 -> 0 | CQ4: Venta | CR4: Propinas | CS4: Venta | CT4: Propinas | CX4: Propinas Totales | CZ4: =CR42+CT42 -> 0 | DD4: Venta | DE4: Propinas | DF4: Venta | DG4: Propinas | DK4: Propinas Totales | DM4: =DE42+DG42 -> 0 | DQ4: Venta | DR4: Propinas | DS4: Venta | DT4: Propinas | DX4: Propinas Totales | DZ4: =DR42+DT42 -> 0 | ED4: Venta | EE4: Propinas | EF4: Venta | EG4: Propinas | EK4: Propinas Totales | EM4: =EE42+EG42 -> 0 | EQ4: Venta | ER4: Propinas | ES4: Venta | ET4: Propinas | EX4: Propinas Totales | EZ4: =ER42+ET42 -> 0
B5: 1406 | C5: 720 | D5: 20 | G5: 60 | H5: HIELO | J5: Gastos totales | L5: =G48 -> 11298 | O5: 3897 | R5: 98 | S5: 9.8 | T5: 140 | U5: carne | W5: Gastos totales | Y5: =T41 -> 5403 | AB5: 4061 | AC5: 258 | AD5: 50 | AG5: 46 | AH5: ALEX | AJ5: Gastos totales | AL5: =AG29 -> 5606.5 | AO5: 818 | AP5: 25 | AT5: 183 | AU5: carne | AW5: Gastos totales | AY5: =AT21 -> 213 | BB5: 759 | BE5: 1375 | BF5: 137.5 | BG5: 50 | BH5: cerveza | BJ5: Gastos totales | BL5: =BG21 -> 1549 | BX5: Gastos totales | BZ5: =BU42 -> 0 | CK5: Gastos totales | CM5: =CH42 -> 0 | CX5: Gastos totales | CZ5: =CU42 -> 0 | DK5: Gastos totales | DM5: =DH42 -> 0 | DX5: Gastos totales | DZ5: =DU42 -> 0 | EK5: Gastos totales | EM5: =EH42 -> 0 | EX5: Gastos totales | EZ5: =EU42 -> 0
C6: 10 | G6: 390 | H6: cervez | J6: Total Caja | L6: =B48+L3+L4-L5-E48-F48 -> -209 | R6: 583 | S6: 58.3 | T6: 2778 | U6: chuy | W6: Total Caja | Y6: =O41+Y3+Y4-Y5-R41-S41 -> 3111 | AE6: 170 | AF6: 17 | AG6: 294.5 | AH6: ahorramas | AJ6: Total Caja | AL6: =AB29+AL3+AL4-AL5-AE29-AF29 -> 402.5 | AR6: 949 | AS6: 94.9 | AT6: 30 | AU6: hielo | AW6: Total Caja | AY6: =AO21+AY3+AY4-AY5-AR21-AS21 -> 1761 | BC6: 45 | BG6: 60 | BH6: hielo | BJ6: Total Caja | BL6: =BB21+BL3+BL4-BL5-BE21-BF21 -> 1272 | BX6: Total Caja | BZ6: =BP42+BZ3+BZ4-BZ5-BS42-BT42 -> 0 | CK6: Total Caja | CM6: =CC42+CM3+CM4-CM5-CF42-CG42 -> 0 | CX6: Total Caja | CZ6: =CP42+CZ3+CZ4-CZ5-CS42-CT42 -> 0 | DK6: Total Caja | DM6: =DC42+DM3+DM4-DM5-DF42-DG42 -> 0 | DX6: Total Caja | DZ6: =DP42+DZ3+DZ4-DZ5-DS42-DT42 -> 0 | EK6: Total Caja | EM6: =EC42+EM3+EM4-EM5-EF42-EG42 -> 0 | EX6: Total Caja | EZ6: =EP42+EZ3+EZ4-EZ5-ES42-ET42 -> 0
C7: 529 | D7: 71 | G7: 550 | H7: carne | K7: Entre 4 | L7: =L4/4 -> 468.3375 | P7: 108 | Q7: 12 | T7: 2485 | U7: claudia | X7: Entre 4 | Y7: =Y4/4 -> 302.375 | AE7: 609 | AF7: 91.35 | AG7: 72 | AH7: ahorramas | AK7: Entre 4 | AL7: =AL4/4 -> 168.7375 | AP7: 481 | AQ7: 80 | AX7: Entre 4 | AY7: =AY4/4 -> 127.125 | BC7: 322 | BD7: 28 | BG7: 23 | BH7: ajo | BK7: Entre 4 | BL7: =BL4/4 -> 133.65 | BY7: Entre 4 | BZ7: =BZ4/4 -> 0 | CL7: Entre 4 | CM7: =CM4/4 -> 0 | CY7: Entre 4 | CZ7: =CZ4/4 -> 0 | DL7: Entre 4 | DM7: =DM4/4 -> 0 | DY7: Entre 4 | DZ7: =DZ4/4 -> 0 | EL7: Entre 4 | EM7: =EM4/4 -> 0 | EY7: Entre 4 | EZ7: =EZ4/4 -> 0
C8: 15 | G8: 4000 | H8: vian | K8: Entre 6 | L8: =L4/6 -> 312.225 | P8: 175 | Q8: 0 | X8: Entre 6 | Y8: =Y4/6 -> 201.58333 | AE8: 291 | AG8: 30 | AH8: hielo | AK8: Entre 6 | AL8: =AL4/6 -> 112.49167 | AR8: 506 | AS8: 50.6 | AX8: Entre 6 | AY8: =AY4/6 -> 84.75 | BC8: 486 | BD8: 56 | BG8: 236 | BH8: mierco lupita | BK8: Entre 6 | BL8: =BL4/6 -> 89.1 | BY8: Entre 6 | BZ8: =BZ4/6 -> 0 | CL8: Entre 6 | CM8: =CM4/6 -> 0 | CY8: Entre 6 | CZ8: =CZ4/6 -> 0 | DL8: Entre 6 | DM8: =DM4/6 -> 0 | DY8: Entre 6 | DZ8: =DZ4/6 -> 0 | EL8: Entre 6 | EM8: =EM4/6 -> 0 | EY8: Entre 6 | EZ8: =EZ4/6 -> 0
C9: 465 | D9: 35 | G9: 30 | H9: aceite | K9: Entre 8 | L9: =L4/8 -> 234.16875 | R9: 222 | S9: 0 | X9: Entre 8 | Y9: =Y4/8 -> 151.1875 | AE9: 224 | AF9: 22 | AG9: 2512 | AH9: Chuy | AK9: Entre 8 | AL9: =AL4/8 -> 84.36875 | AR9: 206 | AS9: 20.6 | AX9: Entre 8 | AY9: =AY4/8 -> 63.5625 | BE9: 176 | BG9: 1180 | BH9: lupita | BK9: Entre 8 | BL9: =BL4/8 -> 66.825 | BY9: Entre 8 | BZ9: =BZ4/8 -> 0 | CL9: Entre 8 | CM9: =CM4/8 -> 0 | CY9: Entre 8 | CZ9: =CZ4/8 -> 0 | DL9: Entre 8 | DM9: =DM4/8 -> 0 | DY9: Entre 8 | DZ9: =DZ4/8 -> 0 | EL9: Entre 8 | EM9: =EM4/8 -> 0 | EY9: Entre 8 | EZ9: =EZ4/8 -> 0
C10: 480 | D10: 50 | E10: 168 | F10: 16.8 | G10: 1690 | H10: rey, falta propina hoy | R10: 438 | S10: 43.8 | AE10: 234 | AG10: 771 | AH10: Ale | AQ10: 100 | AR10: 748 | BC10: 164 | BD10: 16
C11: 278 | D11: 22 | G11: 78 | H11: huevo | P11: 43 | Q11: 10 | AE11: 170 | AG11: 1881 | AH11: Claudia | AR11: 616 | AS11: 92.4 | AZ11: =AVERAGE(AY3,AY26,AY59,AY94,AY129,AY160,AY188,AY219,AY246,AY275,AY304,AY337,AY366,AY397,AY427,AY453,AY479,AY506,AY538,AY567,AY594,AY629,AY654,AY683,AY711,AY740,AY771,AY816,AY839,AY866) -> 5117.0333 | BE11: 903 | BF11: 90.3
C12: 408 | D12: 40 | G12: 4500 | H12: vian | Q12: 40 | R12: 455 | AC12: 142 | AD12: 16 | AP12: 142 | BE12: 387 | BF12: 38.7
C13: 468 | D13: 32 | R13: 708 | S13: 70.8 | AC13: 535 | AD13: 103 | AQ13: 20 | AR13: 465 | BC13: 50
E14: 470 | F14: 23.5 | J14: Turno | K14: Cocina | L14: Mesas | P14: 595 | Q14: 63.5 | W14: Turno | X14: Cocina | Y14: Mesas | AE14: 175 | AF14: 26 | AJ14: Turno | AK14: Cocina | AL14: Mesas | AP14: 258 | AQ14: 50 | AW14: Turno | AX14: Cocina | AY14: Mesas | BC14: 375 | BD14: 40 | BJ14: Turno | BK14: Cocina | BL14: Mesas | BX14: Turno | BY14: Cocina | BZ14: Mesas | CK14: Turno | CL14: Cocina | CM14: Mesas | CX14: Turno | CY14: Cocina | CZ14: Mesas | DK14: Turno | DL14: Cocina | DM14: Mesas | DX14: Turno | DY14: Cocina | DZ14: Mesas | EK14: Turno | EL14: Cocina | EM14: Mesas | EX14: Turno | EY14: Cocina | EZ14: Mesas
E15: 516 | F15: 51.6 | J15: Mañana | K15: mary | L15: valeria | P15: 170 | W15: Mañana | X15: mary | Y15: vianney | AE15: 456 | AF15: 45.6 | AJ15: Mañana | AK15: mary | AL15: Citlali | AW15: Mañana | AX15: mary | AY15: valeria | BC15: 335 | BD15: 35 | BJ15: Mañana | BK15: mary | BL15: valeria | BX15: Mañana | BY15: mary | BZ15: valeria | CK15: Mañana | CL15: mary | CM15: valeria | CX15: Mañana | CY15: mary | CZ15: valeria | DK15: Mañana | DL15: mary | DM15: valeria | DX15: Mañana | DY15: mary | DZ15: valeria | EK15: Mañana | EL15: mary | EM15: valeria | EX15: Mañana | EY15: mary | EZ15: valeria
E16: 816 | F16: 81.6 | J16: Tarde | K16: chuy | L16: andrea | R16: 216 | S16: 21.6 | W16: Tarde | X16: chuy | Y16: Claudia | AC16: 230 | AD16: 22 | AJ16: Tarde | AK16: chuy | AL16: Claudia | AW16: Tarde | AX16: chuy | AY16: andrea | BC16: 110 | BJ16: Tarde | BK16: chuy | BL16: andrea | BX16: Tarde | BY16: chuy | BZ16: andrea | CK16: Tarde | CL16: chuy | CM16: andrea | CX16: Tarde | CY16: chuy | CZ16: andrea | DK16: Tarde | DL16: chuy | DM16: andrea | DX16: Tarde | DY16: chuy | DZ16: andrea | EK16: Tarde | EL16: chuy | EM16: andrea | EX16: Tarde | EY16: chuy | EZ16: andrea
C17: 804 | D17: 0 | P17: 284 | AE17: 442 | AF17: 44.2 | BE17: 407 | BF17: 43
C18: 170 | P18: 178 | Q18: 28 | AE18: 1060 | AF18: 106 | BE18: 1002 | BF18: 50.1
C19: 423 | D19: 47 | P19: 170 | Q19: 30 | AE19: 583 | AF19: 58.3
C20: 64 | R20: 966 | S20: 144.9 | AC20: 157
C21: 441 | D21: 9 | R21: 891 | S21: 89.1 | AE21: 285 | AF21: 28.5 | AO21: =SUM(AO5:AO20) -> 818 | AP21: =SUM(AP5:AP20) -> 906 | AQ21: =SUM(AQ5:AQ20) -> 250 | AR21: =SUM(AR5:AR20) -> 3490 | AS21: =SUM(AS5:AS20) -> 258.5 | AT21: =SUM(AT5:AT20) -> 213 | AU21: Totales | BB21: =SUM(BB5:BB20) -> 759 | BC21: =SUM(BC5:BC20) -> 1887 | BD21: =SUM(BD5:BD20) -> 175 | BE21: =SUM(BE5:BE20) -> 4250 | BF21: =SUM(BF5:BF20) -> 359.6 | BG21: =SUM(BG5:BG20) -> 1549 | BH21: Totales
C22: 599 | D22: 62 | AC22: 165
D23: 28 | E23: 706 | P23: 900 | Q23: 100 | AC23: 225 | AD23: 45
C24: 494 | D24: 56 | R24: 698 | S24: 69.8 | AO24: Jueves 02 de Abril | BB24: Sabado 02 de Mayo
C25: 500 | D25: 70 | R25: 230 | S25: 23
E26: 1613 | F26: 161.3 | R26: 367 | S26: 36.7 | AO26: Caja | AP26: EFECTIVO | AR26: TARJETA | AT26: Gastos | AW26: Ventas Totales | AY26: =AP54+AR54 -> 8793 | BB26: Caja | BC26: EFECTIVO | BE26: TARJETA | BG26: Gastos | BJ26: Ventas Totales | BL26: =BC50+BE50 -> 5729
D27: 50 | E27: 519 | P27: 353 | Q27: 40.5 | AP27: Venta | AQ27: Propinas | AR27: Venta | AS27: Propinas | AW27: Propinas Totales | AY27: =AQ54+AS54 -> 927 | BC27: Venta | BD27: Propinas | BE27: Venta | BF27: Propinas | BJ27: Propinas Totales | BL27: =BD50+BF50 -> 561
C28: 377 | D28: 33 | R28: 433 | S28: 43.3 | AO28: 1761 | AP28: 25 | AT28: 182 | AU28: ahorremas | AW28: Gastos totales | AY28: =AT54 -> 730 | BB28: 572 | BE28: 1074 | BF28: 53.7 | BG28: 38 | BH28: bolsas basura | BJ28: Gastos totales | BL28: =BG50 -> 511
C29: 60 | P29: 8 | AB29: =SUM(AB5:AB28) -> 4061 | AC29: =SUM(AC5:AC28) -> 1712 | AD29: =SUM(AD5:AD28) -> 236 | AE29: =SUM(AE5:AE28) -> 4699 | AF29: =SUM(AF5:AF28) -> 438.95 | AG29: =SUM(AG5:AG28) -> 5606.5 | AH29: Totales | AP29: 527 | AQ29: 53 | AT29: 280 | AU29: kombucha | AW29: Total Caja | AY29: =AO54+AY26+AY27-AY28-AR54-AS54 -> 5770 | BC29: 15 | BG29: 60 | BH29: hielo | BJ29: Total Caja | BL29: =BB50+BL26+BL27-BL28-BE50-BF50 -> 3345
E30: 961 | F30: 96.1 | P30: 8 | AR30: 805 | AS30: 80.5 | AT30: 30 | AU30: hielo | AX30: Entre 4 | AY30: =AY27/4 -> 231.75 | BC30: 104 | BG30: 30 | BH30: molida | BK30: Entre 4 | BL30: =BL27/4 -> 140.25
C31: 10 | P31: 295 | Q31: 30 | AP31: 480 | AQ31: 55 | AT31: 82 | AU31: col morada | AX31: Entre 6 | AY31: =AY27/6 -> 154.5 | BC31: 172 | BD31: 50 | BE31: 374 | BF31: 34.7 | BG31: 383 | BH31: lupita | BK31: Entre 6 | BL31: =BL27/6 -> 93.5
C32: 340 | D32: 30 | P32: 170 | Q32: 10 | AB32: Lunes 2 de marzo de 2026 | AP32: 70 | AT32: 140 | AU32: cerdo | AX32: Entre 8 | AY32: =AY27/8 -> 115.875 | BC32: 175 | BK32: Entre 8 | BL32: =BL27/8 -> 70.125
E33: 648 | F33: 16 | R33: 450 | S33: 45 | AP33: 394 | AQ33: 36 | AT33: 16 | AU33: mango | BC33: 464 | BD33: 36
C34: 25 | R34: 228 | S34: 22.8 | AB34: Caja | AC34: EFECTIVO | AE34: TARJETA | AG34: Gastos | AJ34: Ventas Totales | AL34: =AC55+AE55 -> 2397 | AP34: 286 | AQ34: 27 | BC34: 570 | BD34: 80
D35: 20 | E35: 1511 | F35: 226.65 | R35: 454 | S35: 68.1 | AC35: Venta | AD35: Propinas | AE35: Venta | AF35: Propinas | AJ35: Propinas Totales | AL35: =AD55+AF55 -> 216.5 | AP35: 808 | AQ35: 92 | BC35: 97 | BD35: 20
E36: 727 | F36: 113 | P36: 220 | Q36: 20 | AB36: 412 | AC36: 407 | AD36: 13 | AG36: 158 | AH36: vianney | AJ36: Gastos totales | AL36: =AG55 -> 353 | AR36: 990 | AS36: 99 | BC36: 355 | BD36: 35
E37: 230 | F37: 23 | R37: 285 | S37: 28.5 | AE37: 192 | AF37: 19.2 | AG37: 25 | AH37: hielo | AJ37: Total Caja | AL37: =AB55+AL34+AL35-AL36-AE55-AF55 -> 1293 | AR37: 428 | AS37: 42.8 | AW37: Turno | AX37: Cocina | AY37: Mesas | BC37: 254 | BJ37: Turno | BK37: Cocina | BL37: Mesas
C38: 220 | D38: 20 | P38: 76 | AE38: 338 | AF38: 67.6 | AG38: 170 | AH38: cerdo | AK38: Entre 4 | AL38: =AL35/4 -> 54.125 | AP38: 1206 | AQ38: 150 | AW38: Mañana | AX38: mary | AY38: Lupita | BC38: 427 | BD38: 93 | BJ38: Mañana | BK38: chuy | BL38: Vianney
E39: 175 | F39: 17.5 | P39: 430 | Q39: 50 | AC39: 142 | AD39: 20 | AK39: Entre 6 | AL39: =AL35/6 -> 36.083333 | AP39: 15 | AW39: Tarde | AX39: chuy | AY39: ruth | BE39: 848 | BF39: 84.8 | BJ39: Tarde | BK39: mary | BL39: Lupita
E40: 625 | F40: 62.5 | AD40: 40 | AE40: 381 | AK40: Entre 8 | AL40: =AL35/8 -> 27.0625 | AP40: 170 | BC40: 230 | BD40: 25
E41: 941 | F41: 94.1 | O41: =SUM(O5:O40) -> 3897 | P41: =SUM(P5:P40) -> 4183 | Q41: =SUM(Q5:Q40) -> 434 | R41: =SUM(R5:R40) -> 7722 | S41: =SUM(S5:S40) -> 775.5 | T41: =SUM(T5:T40) -> 5403 | U41: Totales | AE41: 213 | AF41: 21.3 | AP41: 35 | BC41: 72
...

Sheet RELACIONES
B2: ENERO | C2: ENTRADAS | D2: SALIDAS | E2: TOTAL | G2: FEBERO | H2: ENTRADAS | I2: SALIDAS | J2: TOTAL | L2: MARZO | M2: ENTRADAS | N2: SALIDAS | O2: TOTAL | Q2: ABRIL | R2: ENTRADAS | S2: SALIDAS | T2: TOTAL | V2: MAYO | W2: ENTRADAS | X2: SALIDAS | Y2: TOTAL | AA2: JUNIO | AB2: ENTRADAS | AC2: SALIDAS | AD2: TOTAL | AF2: JULIO | AG2: ENTRADAS | AH2: SALIDAS | AI2: TOTAL | AK2: AGOSTO | AL2: ENTRADAS | AM2: SALIDAS | AN2: TOTAL | AP2: SEPTIEMBRE | AQ2: ENTRADAS | AR2: SALIDAS | AS2: TOTAL | AU2: OCTUBRE | AV2: ENTRADAS | AW2: SALIDAS | AX2: TOTAL | AZ2: NOVIEMBRE | BA2: ENTRADAS | BB2: SALIDAS | BC2: TOTAL | BE2: DICIEMBRE | BF2: ENTRADAS | BG2: SALIDAS | BH2: TOTAL
B3: 45658 | C3: 8639 | D3: 1948 | E3: =C3-D3 -> 6691 | G3: 45689 | H3: 10869 | I3: 2281 | J3: =H3-I3 -> 8588 | L3: 45717 | M3: 10023 | N3: 2860 | O3: =M3-N3 -> 7163 | Q3: 45748 | R3: 2983 | S3: 448 | T3: =R3-S3 -> 2535 | V3: 45778 | W3: 8698 | X3: 3878 | Y3: =W3-X3 -> 4820 | AA3: 45809 | AB3: 4925 | AC3: 3344 | AD3: =AB3-AC3 -> 1581 | AF3: 45839 | AG3: 6520 | AH3: 797 | AI3: =AG3-AH3 -> 5723 | AK3: 45870 | AN3: =AL3-AM3 -> 0 | AP3: 45901 | AQ3: 6096 | AS3: =AQ3-AR3 -> 6096 | AU3: 45931 | AV3: 3801 | AX3: =AV3-AW3 -> 3801 | AZ3: 45962 | BA3: 13890 | BC3: =BA3-BB3 -> 13890 | BE3: 45992 | BH3: =BF3-BG3 -> 0
B4: 45659 | C4: 9087 | D4: 3945 | E4: =C4-D4 -> 5142 | G4: 45690 | H4: 13150 | I4: 3469 | J4: =H4-I4 -> 9681 | L4: 45718 | M4: 10271 | N4: 4745 | O4: =M4-N4 -> 5526 | Q4: 45749 | R4: 7972 | S4: 2558 | T4: =R4-S4 -> 5414 | V4: 45779 | W4: 4143 | X4: 1816 | Y4: =W4-X4 -> 2327 | AA4: 45810 | AB4: 5997 | AC4: 3678 | AD4: =AB4-AC4 -> 2319 | AF4: 45840 | AG4: 3360 | AH4: 5206 | AI4: =AG4-AH4 -> -1846 | AK4: 45871 | AN4: =AL4-AM4 -> 0 | AP4: 45902 | AQ4: 2941 | AS4: =AQ4-AR4 -> 2941 | AU4: 45932 | AV4: 2923 | AX4: =AV4-AW4 -> 2923 | AZ4: 45963 | BA4: 23631 | BC4: =BA4-BB4 -> 23631 | BE4: 45993 | BH4: =BF4-BG4 -> 0
B5: 45660 | C5: 6358 | D5: 2800 | E5: =C5-D5 -> 3558 | G5: 45691 | H5: 10475 | I5: 2554 | J5: =H5-I5 -> 7921 | L5: 45719 | M5: 8248 | N5: 2804 | O5: =M5-N5 -> 5444 | Q5: 45750 | R5: 3528 | S5: 3550 | T5: =R5-S5 -> -22 | V5: 45780 | W5: 9084 | X5: 1037 | Y5: =W5-X5 -> 8047 | AA5: 45811 | AB5: 6325 | AC5: 1234 | AD5: =AB5-AC5 -> 5091 | AF5: 45841 | AG5: 3216 | AH5: 2501 | AI5: =AG5-AH5 -> 715 | AK5: 45872 | AN5: =AL5-AM5 -> 0 | AP5: 45903 | AQ5: 2458 | AS5: =AQ5-AR5 -> 2458 | AU5: 45933 | AV5: 3135 | AX5: =AV5-AW5 -> 3135 | AZ5: 45964 | BA5: 13742 | BC5: =BA5-BB5 -> 13742 | BE5: 45994 | BH5: =BF5-BG5 -> 0
B6: 45661 | C6: 9668 | D6: 1626 | E6: =C6-D6 -> 8042 | G6: 45692 | H6: 3138 | I6: 695 | J6: =H6-I6 -> 2443 | L6: 45720 | M6: 5277 | N6: 2816 | O6: =M6-N6 -> 2461 | Q6: 45751 | R6: 2896 | S6: 2819 | T6: =R6-S6 -> 77 | V6: 45781 | W6: 6157 | X6: 5365 | Y6: =W6-X6 -> 792 | AA6: 45812 | AB6: 4519 | AC6: 151 | AD6: =AB6-AC6 -> 4368 | AF6: 45842 | AG6: 2371 | AH6: 1547 | AI6: =AG6-AH6 -> 824 | AK6: 45873 | AN6: =AL6-AM6 -> 0 | AP6: 45904 | AQ6: 3077 | AS6: =AQ6-AR6 -> 3077 | AU6: 45934 | AV6: 6426 | AX6: =AV6-AW6 -> 6426 | AZ6: 45965 | BA6: 6490 | BC6: =BA6-BB6 -> 6490 | BE6: 45995 | BH6: =BF6-BG6 -> 0
B7: 45662 | C7: 13172 | D7: 6365 | E7: =C7-D7 -> 6807 | G7: 45693 | H7: 2904 | I7: 2542 | J7: =H7-I7 -> 362 | L7: 45721 | M7: 5085 | N7: 58 | O7: =M7-N7 -> 5027 | Q7: 45752 | R7: 5330 | S7: 505 | T7: =R7-S7 -> 4825 | V7: 45782 | W7: 6147 | X7: 1695 | Y7: =W7-X7 -> 4452 | AA7: 45813 | AB7: 5627 | AC7: 1121 | AD7: =AB7-AC7 -> 4506 | AF7: 45843 | AG7: 10431 | AH7: 3431 | AI7: =AG7-AH7 -> 7000 | AK7: 45874 | AN7: =AL7-AM7 -> 0 | AP7: 45905 | AQ7: 5442 | AS7: =AQ7-AR7 -> 5442 | AU7: 45935 | AV7: 7545 | AX7: =AV7-AW7 -> 7545 | AZ7: 45966 | BA7: 8557 | BC7: =BA7-BB7 -> 8557 | BE7: 45996 | BH7: =BF7-BG7 -> 0
B8: 45663 | C8: 6995 | D8: 6824 | E8: =C8-D8 -> 171 | G8: 45694 | H8: 3898 | I8: 2358 | J8: =H8-I8 -> 1540 | L8: 45722 | M8: 5719 | N8: 2270 | O8: =M8-N8 -> 3449 | Q8: 45753 | R8: 11719 | S8: 4229 | T8: =R8-S8 -> 7490 | V8: 45783 | W8: 6605 | X8: 714 | Y8: =W8-X8 -> 5891 | AA8: 45814 | AB8: 5572 | AC8: 2620 | AD8: =AB8-AC8 -> 2952 | AF8: 45844 | AG8: 7842 | AH8: 3124 | AI8: =AG8-AH8 -> 4718 | AK8: 45875 | AN8: =AL8-AM8 -> 0 | AP8: 45906 | AQ8: 8410 | AS8: =AQ8-AR8 -> 8410 | AU8: 45936 | AV8: 6810 | AX8: =AV8-AW8 -> 6810 | AZ8: 45967 | BA8: 8280 | BC8: =BA8-BB8 -> 8280 | BE8: 45997 | BH8: =BF8-BG8 -> 0
B9: 45664 | C9: 10272 | D9: 4669 | E9: =C9-D9 -> 5603 | G9: 45695 | H9: 5863 | I9: 3861 | J9: =H9-I9 -> 2002 | L9: 45723 | M9: 7246 | N9: 2828 | O9: =M9-N9 -> 4418 | Q9: 45754 | R9: 6132 | S9: 2927 | T9: =R9-S9 -> 3205 | V9: 45784 | W9: 2596 | X9: 225 | Y9: =W9-X9 -> 2371 | AA9: 45815 | AB9: 6958 | AC9: 118 | AD9: =AB9-AC9 -> 6840 | AF9: 45845 | AG9: 5056 | AH9: 2469 | AI9: =AG9-AH9 -> 2587 | AK9: 45876 | AN9: =AL9-AM9 -> 0 | AP9: 45907 | AQ9: 5310 | AS9: =AQ9-AR9 -> 5310 | AU9: 45937 | AV9: 4737 | AX9: =AV9-AW9 -> 4737 | AZ9: 45968 | BA9: 8197 | BC9: =BA9-BB9 -> 8197 | BE9: 45998 | BH9: =BF9-BG9 -> 0
B10: 45665 | C10: 3401 | D10: 643 | E10: =C10-D10 -> 2758 | G10: 45696 | H10: 6864 | I10: 1340 | J10: =H10-I10 -> 5524 | L10: 45724 | M10: 8481 | N10: 3521 | O10: =M10-N10 -> 4960 | Q10: 45755 | R10: 8390 | S10: 851 | T10: =R10-S10 -> 7539 | V10: 45785 | W10: 4218 | X10: 2075 | Y10: =W10-X10 -> 2143 | AA10: 45816 | AB10: 7068 | AC10: 3121 | AD10: =AB10-AC10 -> 3947 | AF10: 45846 | AG10: 5837 | AH10: 1027 | AI10: =AG10-AH10 -> 4810 | AK10: 45877 | AN10: =AL10-AM10 -> 0 | AP10: 45908 | AQ10: 911 | AS10: =AQ10-AR10 -> 911 | AU10: 45938 | AV10: 5849 | AX10: =AV10-AW10 -> 5849 | AZ10: 45969 | BA10: 7632 | BC10: =BA10-BB10 -> 7632 | BE10: 45999 | BH10: =BF10-BG10 -> 0
B11: 45666 | C11: 3513 | D11: 3254 | E11: =C11-D11 -> 259 | G11: 45697 | H11: 7817 | I11: 5091 | J11: =H11-I11 -> 2726 | L11: 45725 | M11: 7830 | N11: 1945 | O11: =M11-N11 -> 5885 | Q11: 45756 | R11: 5977 | S11: 212 | T11: =R11-S11 -> 5765 | V11: 45786 | W11: 3715 | X11: 3266 | Y11: =W11-X11 -> 449 | AA11: 45817 | AB11: 2907 | AC11: 593 | AD11: =AB11-AC11 -> 2314 | AF11: 45847 | AG11: 3288 | AH11: 181 | AI11: =AG11-AH11 -> 3107 | AK11: 45878 | AN11: =AL11-AM11 -> 0 | AP11: 45909 | AQ11: 5592 | AS11: =AQ11-AR11 -> 5592 | AU11: 45939 | AV11: 3684 | AX11: =AV11-AW11 -> 3684 | AZ11: 45970 | BA11: 7559 | BC11: =BA11-BB11 -> 7559 | BE11: 46000 | BH11: =BF11-BG11 -> 0
B12: 45667 | C12: 3280 | D12: 1931 | E12: =C12-D12 -> 1349 | G12: 45698 | H12: 4779 | I12: 3742 | J12: =H12-I12 -> 1037 | L12: 45726 | M12: 3033 | N12: 2874 | O12: =M12-N12 -> 159 | Q12: 45757 | R12: 4001 | S12: 4184 | T12: =R12-S12 -> -183 | V12: 45787 | W12: 2905 | X12: 442 | Y12: =W12-X12 -> 2463 | AA12: 45818 | AB12: 4614 | AC12: 4204 | AD12: =AB12-AC12 -> 410 | AF12: 45848 | AG12: 6029 | AH12: 5863 | AI12: =AG12-AH12 -> 166 | AK12: 45879 | AN12: =AL12-AM12 -> 0 | AP12: 45910 | AQ12: 4956 | AS12: =AQ12-AR12 -> 4956 | AU12: 45940 | AV12: 3311 | AX12: =AV12-AW12 -> 3311 | AZ12: 45971 | BA12: 7151 | BC12: =BA12-BB12 -> 7151 | BE12: 46001 | BH12: =BF12-BG12 -> 0
B13: 45668 | C13: 5175 | D13: 1463 | E13: =C13-D13 -> 3712 | G13: 45699 | H13: 6194 | I13: 1217 | J13: =H13-I13 -> 4977 | L13: 45727 | M13: 4417 | N13: 3527 | O13: =M13-N13 -> 890 | Q13: 45758 | R13: 14263 | S13: 4061 | T13: =R13-S13 -> 10202 | V13: 45788 | W13: 3933 | X13: 2176 | Y13: =W13-X13 -> 1757 | AA13: 45819 | AB13: 4424 | AC13: 348 | AD13: =AB13-AC13 -> 4076 | AF13: 45849 | AG13: 3337 | AH13: 783 | AI13: =AG13-AH13 -> 2554 | AK13: 45880 | AN13: =AL13-AM13 -> 0 | AP13: 45911 | AQ13: 3929 | AS13: =AQ13-AR13 -> 3929 | AU13: 45941 | AV13: 11787 | AX13: =AV13-AW13 -> 11787 | AZ13: 45972 | BA13: 7027 | BC13: =BA13-BB13 -> 7027 | BE13: 46002 | BH13: =BF13-BG13 -> 0
B14: 45669 | C14: 8768 | D14: 2591 | E14: =C14-D14 -> 6177 | G14: 45700 | H14: 6227 | I14: 523 | J14: =H14-I14 -> 5704 | L14: 45728 | M14: 6364 | N14: 3143 | O14: =M14-N14 -> 3221 | Q14: 45759 | R14: 5941 | S14: 1485 | T14: =R14-S14 -> 4456 | V14: 45789 | W14: 2605 | X14: 2354 | Y14: =W14-X14 -> 251 | AA14: 45820 | AB14: 7035 | AC14: 4137 | AD14: =AB14-AC14 -> 2898 | AF14: 45850 | AG14: 12954 | AH14: 7635 | AI14: =AG14-AH14 -> 5319 | AK14: 45881 | AN14: =AL14-AM14 -> 0 | AP14: 45912 | AQ14: 3289 | AS14: =AQ14-AR14 -> 3289 | AU14: 45942 | AV14: 11769 | AX14: =AV14-AW14 -> 11769 | AZ14: 45973 | BA14: 4018 | BC14: =BA14-BB14 -> 4018 | BE14: 46003 | BH14: =BF14-BG14 -> 0
... B17: 45672 | C17: 5969 | D17: 1148 | E17: =C17-D17 -> 4821 | G17: 45703 | H17: 10695 | I17: 3625 | J17: =H17-I17 -> 7070 | L17: 45731 | M17: 12300 | N17: 4823 | O17: =M17-N17 -> 7477 | Q17: 45762 | R17: 9458 | S17: 1275 | T17: =R17-S17 -> 8183 | V17: 45792 | W17: 1136 | X17: 258 | Y17: =W17-X17 -> 878 | AA17: 45823 | AB17: 4702 | AC17: 3452 | AD17: =AB17-AC17 -> 1250 | AF17: 45853 | AG17: 6121 | AH17: 707 | AI17: =AG17-AH17 -> 5414 | AK17: 45884 | AN17: =AL17-AM17 -> 0 | AP17: 45915 | AQ17: 9245 | AS17: =AQ17-AR17 -> 9245 | AU17: 45945 | AV17: 7493 | AX17: =AV17-AW17 -> 7493 | AZ17: 45976 | BA17: 8914 | BC17: =BA17-BB17 -> 8914 | BE17: 46006 | BH17: =BF17-BG17 -> 0
B18: 45673 | C18: 3081 | D18: 2846 | E18: =C18-D18 -> 235 | G18: 45704 | H18: 11700 | I18: 2221 | J18: =H18-I18 -> 9479 | L18: 45732 | M18: 13538 | N18: 3829 | O18: =M18-N18 -> 9709 | Q18: 45763 | R18: 5278 | S18: 707 | T18: =R18-S18 -> 4571 | V18: 45793 | W18: 4083 | X18: 1567 | Y18: =W18-X18 -> 2516 | AA18: 45824 | AB18: 4656 | AC18: 2281 | AD18: =AB18-AC18 -> 2375 | AF18: 45854 | AI18: =AG18-AH18 -> 0 | AK18: 45885 | AN18: =AL18-AM18 -> 0 | AP18: 45916 | AQ18: 7849 | AS18: =AQ18-AR18 -> 7849 | AU18: 45946 | AV18: 7379 | AX18: =AV18-AW18 -> 7379 | AZ18: 45977 | BA18: 8689 | BC18: =BA18-BB18 -> 8689 | BE18: 46007 | BH18: =BF18-BG18 -> 0
B19: 45674 | C19: 5502 | D19: 2230 | E19: =C19-D19 -> 3272 | G19: 45705 | H19: 7602 | I19: 3205 | J19: =H19-I19 -> 4397 | L19: 45733 | M19: 10933 | N19: 5740 | O19: =M19-N19 -> 5193 | Q19: 45764 | R19: 6413 | S19: 307 | T19: =R19-S19 -> 6106 | V19: 45794 | W19: 3159 | X19: 1688 | Y19: =W19-X19 -> 1471 | AA19: 45825 | AB19: 6430 | AC19: 1170 | AD19: =AB19-AC19 -> 5260 | AF19: 45855 | AI19: =AG19-AH19 -> 0 | AK19: 45886 | AN19: =AL19-AM19 -> 0 | AP19: 45917 | AQ19: 6434 | AS19: =AQ19-AR19 -> 6434 | AU19: 45947 | AV19: 14203 | AX19: =AV19-AW19 -> 14203 | AZ19: 45978 | BA19: 7853 | BC19: =BA19-BB19 -> 7853 | BE19: 46008 | BH19: =BF19-BG19 -> 0
B20: 45675 | C20: 9164 | D20: 1377 | E20: =C20-D20 -> 7787 | G20: 45706 | H20: 7883 | I20: 5668 | J20: =H20-I20 -> 2215 | L20: 45734 | M20: 4295 | N20: 674 | O20: =M20-N20 -> 3621 | Q20: 45765 | R20: 8638 | S20: 4960 | T20: =R20-S20 -> 3678 | V20: 45795 | W20: 4165 | X20: 4210 | Y20: =W20-X20 -> -45 | AA20: 45826 | AB20: 5901 | AC20: 1345 | AD20: =AB20-AC20 -> 4556 | AF20: 45856 | AI20: =AG20-AH20 -> 0 | AK20: 45887 | AN20: =AL20-AM20 -> 0 | AP20: 45918 | AQ20: 3011 | AS20: =AQ20-AR20 -> 3011 | AU20: 45948 | AV20: 20080 | AX20: =AV20-AW20 -> 20080 | AZ20: 45979 | BA20: 2913 | BC20: =BA20-BB20 -> 2913 | BE20: 46009 | BH20: =BF20-BG20 -> 0
B21: 45676 | C21: 5187 | D21: 2380 | E21: =C21-D21 -> 2807 | G21: 45707 | H21: 4397 | I21: 1201 | J21: =H21-I21 -> 3196 | L21: 45735 | M21: 8102 | N21: 895 | O21: =M21-N21 -> 7207 | Q21: 45766 | R21: 9139 | S21: 754 | T21: =R21-S21 -> 8385 | V21: 45796 | W21: 3853 | X21: 541 | Y21: =W21-X21 -> 3312 | AA21: 45827 | AB21: 4016 | AC21: 2975 | AD21: =AB21-AC21 -> 1041 | AF21: 45857 | AI21: =AG21-AH21 -> 0 | AK21: 45888 | AN21: =AL21-AM21 -> 0 | AP21: 45919 | AQ21: 3638 | AS21: =AQ21-AR21 -> 3638 | AU21: 45949 | AV21: 16061 | AX21: =AV21-AW21 -> 16061 | AZ21: 45980 | BA21: 3928 | BC21: =BA21-BB21 -> 3928 | BE21: 46010 | BH21: =BF21-BG21 -> 0
B22: 45677 | C22: 6740 | D22: 5494 | E22: =C22-D22 -> 1246 | G22: 45708 | H22: 5954 | I22: 5452 | J22: =H22-I22 -> 502 | L22: 45736 | M22: 6239 | N22: 5284 | O22: =M22-N22 -> 955 | Q22: 45767 | R22: 6948 | S22: 6137 | T22: =R22-S22 -> 811 | V22: 45797 | W22: 3323 | X22: 408 | Y22: =W22-X22 -> 2915 | AA22: 45828 | AB22: 1318 | AC22: 288 | AD22: =AB22-AC22 -> 1030 | AF22: 45858 | AI22: =AG22-AH22 -> 0 | AK22: 45889 | AN22: =AL22-AM22 -> 0 | AP22: 45920 | AQ22: 9781 | AS22: =AQ22-AR22 -> 9781 | AU22: 45950 | AV22: 8238 | AX22: =AV22-AW22 -> 8238 | AZ22: 45981 | BA22: 2558 | BC22: =BA22-BB22 -> 2558 | BE22: 46011 | BH22: =BF22-BG22 -> 0
B23: 45678 | C23: 5117 | D23: 1166 | E23: =C23-D23 -> 3951 | G23: 45709 | H23: 8752 | I23: 6088 | J23: =H23-I23 -> 2664 | L23: 45737 | M23: 6582 | N23: 2409 | O23: =M23-N23 -> 4173 | Q23: 45768 | R23: 5159 | S23: 3015 | T23: =R23-S23 -> 2144 | V23: 45798 | W23: 1104 | X23: 108 | Y23: =W23-X23 -> 996 | AA23: 45829 | AB23: 4128 | AC23: 939 | AD23: =AB23-AC23 -> 3189 | AF23: 45859 | AI23: =AG23-AH23 -> 0 | AK23: 45890 | AN23: =AL23-AM23 -> 0 | AP23: 45921 | AQ23: 5340 | AS23: =AQ23-AR23 -> 5340 | AU23: 45951 | AV23: 10279 | AX23: =AV23-AW23 -> 10279 | AZ23: 45982 | BA23: 4668 | BC23: =BA23-BB23 -> 4668 | BE23: 46012 | BH23: =BF23-BG23 -> 0
B24: 45679 | C24: 3983 | D24: 1030 | E24: =C24-D24 -> 2953 | G24: 45710 | H24: 8888 | I24: 1642 | J24: =H24-I24 -> 7246 | L24: 45738 | M24: 11077 | N24: 4749 | O24: =M24-N24 -> 6328 | Q24: 45769 | R24: 2456 | S24: 1385 | T24: =R24-S24 -> 1071 | V24: 45799 | W24: 6043 | X24: 3259 | Y24: =W24-X24 -> 2784 | AA24: 45830 | AB24: 8555 | AC24: 4643 | AD24: =AB24-AC24 -> 3912 | AF24: 45860 | AI24: =AG24-AH24 -> 0 | AK24: 45891 | AN24: =AL24-AM24 -> 0 | AP24: 45922 | AQ24: 5364 | AS24: =AQ24-AR24 -> 5364 | AU24: 45952 | AV24: 7182 | AX24: =AV24-AW24 -> 7182 | AZ24: 45983 | BA24: 11311 | BC24: =BA24-BB24 -> 11311 | BE24: 46013 | BH24: =BF24-BG24 -> 0
B25: 45680 | C25: 4960 | D25: 2433 | E25: =C25-D25 -> 2527 | G25: 45711 | H25: 10482 | I25: 7365 | J25: =H25-I25 -> 3117 | L25: 45739 | M25: 9332 | N25: 5976 | O25: =M25-N25 -> 3356 | Q25: 45770 | R25: 3623 | S25: 300 | T25: =R25-S25 -> 3323 | V25: 45800 | W25: 6258 | X25: 2224 | Y25: =W25-X25 -> 4034 | AA25: 45831 | AB25: 1955 | AC25: 2270 | AD25: =AB25-AC25 -> -315 | AF25: 45861 | AI25: =AG25-AH25 -> 0 | AK25: 45892 | AN25: =AL25-AM25 -> 0 | AP25: 45923 | AQ25: 6339 | AS25: =AQ25-AR25 -> 6339 | AU25: 45953 | AV25: 8307 | AX25: =AV25-AW25 -> 8307 | AZ25: 45984 | BA25: 7972 | BC25: =BA25-BB25 -> 7972 | BE25: 46014 | BH25: =BF25-BG25 -> 0
B26: 45681 | C26: 5075 | D26: 2080 | E26: =C26-D26 -> 2995 | G26: 45712 | H26: 6379 | I26: 2961 | J26: =H26-I26 -> 3418 | L26: 45740 | M26: 8605 | N26: 3438 | O26: =M26-N26 -> 5167 | Q26: 45771 | R26: 4223 | S26: 3705 | T26: =R26-S26 -> 518 | V26: 45801 | W26: 7127 | X26: 1829 | Y26: =W26-X26 -> 5298 | AA26: 45832 | AB26: 4359 | AC26: 563 | AD26: =AB26-AC26 -> 3796 | AF26: 45862 | AI26: =AG26-AH26 -> 0 | AK26: 45893 | AN26: =AL26-AM26 -> 0 | AP26: 45924 | AQ26: 2235 | AS26: =AQ26-AR26 -> 2235 | AU26: 45954 | AV26: 11935 | AX26: =AV26-AW26 -> 11935 | AZ26: 45985 | BA26: 4896 | BC26: =BA26-BB26 -> 4896 | BE26: 46015 | BH26: =BF26-BG26 -> 0
B27: 45682 | C27: 8919 | D27: 7185 | E27: =C27-D27 -> 1734 | G27: 45713 | H27: 7304 | I27: 1429 | J27: =H27-I27 -> 5875 | L27: 45741 | M27: 7305 | N27: 786 | O27: =M27-N27 -> 6519 | Q27: 45772 | R27: 2195 | S27: 1765 | T27: =R27-S27 -> 430 | V27: 45802 | W27: 10005 | X27: 3935 | Y27: =W27-X27 -> 6070 | AA27: 45833 | AB27: 6231 | AC27: 1922 | AD27: =AB27-AC27 -> 4309 | AF27: 45863 | AI27: =AG27-AH27 -> 0 | AK27: 45894 | AN27: =AL27-AM27 -> 0 | AP27: 45925 | AQ27: 3212 | AS27: =AQ27-AR27 -> 3212 | AU27: 45955 | AV27: 17854 | AX27: =AV27-AW27 -> 17854 | AZ27: 45986 | BA27: 4408 | BC27: =BA27-BB27 -> 4408 | BE27: 46016 | BH27: =BF27-BG27 -> 0
B28: 45683 | C28: 5898 | D28: 2455 | E28: =C28-D28 -> 3443 | G28: 45714 | H28: 4492 | I28: 1092 | J28: =H28-I28 -> 3400 | L28: 45742 | M28: 4257 | N28: 176 | O28: =M28-N28 -> 4081 | Q28: 45773 | R28: 7318 | S28: 1086 | T28: =R28-S28 -> 6232 | V28: 45803 | W28: 2791 | X28: 795 | Y28: =W28-X28 -> 1996 | AA28: 45834 | AB28: 5058 | AC28: 3734 | AD28: =AB28-AC28 -> 1324 | AF28: 45864 | AI28: =AG28-AH28 -> 0 | AK28: 45895 | AN28: =AL28-AM28 -> 0 | AP28: 45926 | AQ28: 4018 | AS28: =AQ28-AR28 -> 4018 | AU28: 45956 | AV28: 11808 | AX28: =AV28-AW28 -> 11808 | AZ28: 45987 | BC28: =BA28-BB28 -> 0 | BE28: 46017 | BH28: =BF28-BG28 -> 0
B29: 45684 | C29: 6030 | D29: 2880 | E29: =C29-D29 -> 3150 | G29: 45715 | H29: 5493 | I29: 764 | J29: =H29-I29 -> 4729 | L29: 45743 | M29: 4091 | N29: 3690 | O29: =M29-N29 -> 401 | Q29: 45774 | R29: 3548 | S29: 470 | T29: =R29-S29 -> 3078 | V29: 45804 | W29: 2860 | X29: 453 | Y29: =W29-X29 -> 2407 | AA29: 45835 | AB29: 6980 | AC29: 1947 | AD29: =AB29-AC29 -> 5033 | AF29: 45865 | AI29: =AG29-AH29 -> 0 | AK29: 45896 | AN29: =AL29-AM29 -> 0 | AP29: 45927 | AQ29: 7110 | AS29: =AQ29-AR29 -> 7110 | AU29: 45957 | AV29: 5828 | AX29: =AV29-AW29 -> 5828 | AZ29: 45988 | BC29: =BA29-BB29 -> 0 | BE29: 46018 | BH29: =BF29-BG29 -> 0
B30: 45685 | C30: 5083 | D30: 653 | E30: =C30-D30 -> 4430 | G30: 45716 | H30: 9082 | I30: 3949 | J30: =H30-I30 -> 5133 | L30: 45744 | M30: 8543 | N30: 4691 | O30: =M30-N30 -> 3852 | Q30: 45775 | R30: 3291 | S30: 87 | T30: =R30-S30 -> 3204 | V30: 45805 | W30: 2593 | X30: 58 | Y30: =W30-X30 -> 2535 | AA30: 45836 | AB30: 7978 | AC30: 3341 | AD30: =AB30-AC30 -> 4637 | AF30: 45866 | AI30: =AG30-AH30 -> 0 | AK30: 45897 | AN30: =AL30-AM30 -> 0 | AP30: 45928 | AQ30: 6841 | AS30: =AQ30-AR30 -> 6841 | AU30: 45958 | AV30: 7883 | AX30: =AV30-AW30 -> 7883 | AZ30: 45989 | BC30: =BA30-BB30 -> 0 | BE30: 46019 | BH30: =BF30-BG30 -> 0
B31: 45686 | C31: 5184 | D31: 216 | E31: =C31-D31 -> 4968 | G31: 45717 | J31: =H31-I31 -> 0 | L31: 45745 | M31: 9355 | N31: 4235 | O31: =M31-N31 -> 5120 | Q31: 45776 | R31: 3288 | S31: 380 | T31: =R31-S31 -> 2908 | V31: 45806 | W31: 4566 | X31: 2791 | Y31: =W31-X31 -> 1775 | AA31: 45837 | AB31: 5561 | AC31: 4495 | AD31: =AB31-AC31 -> 1066 | AF31: 45867 | AI31: =AG31-AH31 -> 0 | AK31: 45898 | AN31: =AL31-AM31 -> 0 | AP31: 45929 | AQ31: 6029 | AS31: =AQ31-AR31 -> 6029 | AU31: 45959 | AV31: 7076 | AX31: =AV31-AW31 -> 7076 | AZ31: 45990 | BC31: =BA31-BB31 -> 0 | BE31: 46020 | BH31: =BF31-BG31 -> 0
B32: 45687 | C32: 3663 | D32: 2811 | E32: =C32-D32 -> 852 | G32: 45718 | J32: =H32-I32 -> 0 | L32: 45746 | M32: 6682 | N32: 3686 | O32: =M32-N32 -> 2996 | Q32: 45777 | R32: 4015 | S32: 90 | T32: =R32-S32 -> 3925 | V32: 45807 | W32: 7700 | X32: 2915 | Y32: =W32-X32 -> 4785 | AA32: 45838 | AB32: 2330 | AC32: 2353 | AD32: =AB32-AC32 -> -23 | AF32: 45868 | AI32: =AG32-AH32 -> 0 | AK32: 45899 | AN32: =AL32-AM32 -> 0 | AP32: 45930 | AQ32: 5282 | AS32: =AQ32-AR32 -> 5282 | AU32: 45960 | AV32: 7712 | AX32: =AV32-AW32 -> 7712 | AZ32: 45991 | BC32: =BA32-BB32 -> 0 | BE32: 46021 | BH32: =BF32-BG32 -> 0
B33: 45688 | C33: 4121 | D33: 1803 | E33: =C33-D33 -> 2318 | G33: 45719 | J33: =H33-I33 -> 0 | L33: 45747 | M33: 6459 | N33: 2690 | O33: =M33-N33 -> 3769 | Q33: 45778 | T33: =R33-S33 -> 0 | V33: 45808 | W33: 8826 | X33: 1196 | Y33: =W33-X33 -> 7630 | AA33: 45839 | AD33: =AB33-AC33 -> 0 | AF33: 45869 | AI33: =AG33-AH33 -> 0 | AK33: 45900 | AN33: =AL33-AM33 -> 0 | AP33: 45931 | AS33: =AQ33-AR33 -> 0 | AU33: 45961 | AV33: 7790 | AX33: =AV33-AW33 -> 7790 | AZ33: 45992 | BC33: =BA33-BB33 -> 0 | BE33: 46022 | BH33: =BF33-BG33 -> 0
B34: TOTALES | C34: =SUM(C3:C33) -> 197993 | D34: =SUM(D3:D33) -> 83514 | E34: =SUM(E3:E33) -> 114479 | G34: TOTALES | H34: =SUM(H3:H33) -> 207830 | I34: =SUM(I3:I33) -> 81796 | J34: =SUM(J3:J33) -> 126034 | L34: TOTALES | M34: =SUM(M3:M33) -> 234449 | N34: =SUM(N3:N33) -> 98729 | O34: =SUM(O3:O33) -> 135720 | Q34: TOTALES | R34: =SUM(R3:R33) -> 178096 | S34: =SUM(S3:S33) -> 62364 | T34: =SUM(T3:T33) -> 115732 | V34: TOTALES | W34: =SUM(W3:W33) -> 149925 | X34: =SUM(X3:X33) -> 55384 | Y34: =SUM(Y3:Y33) -> 94541 | AA34: TOTALES | AB34: =SUM(AB3:AB33) -> 156863 | AC34: =SUM(AC3:AC33) -> 66568 | AD34: =SUM(AD3:AD33) -> 90295 | AF34: TOTALES | AG34: =SUM(AG3:AG33) -> 87461 | AH34: =SUM(AH3:AH33) -> 41907 | AI34: =SUM(AI3:AI33) -> 45554 | AK34: TOTALES | AL34: =SUM(AL3:AL33) -> 0 | AM34: =SUM(AM3:AM33) -> 0 | AN34: =SUM(AN3:AN33) -> 0 | AP34: TOTALES | AQ34: =SUM(AQ3:AQ33) -> 161316 | AR34: =SUM(AR3:AR33) -> 0 | AS34: =SUM(AS3:AS33) -> 161316 | AU34: TOTALES | AV34: =SUM(AV3:AV33) -> 266808 | AW34: =SUM(AW3:AW33) -> 0 | AX34: =SUM(AX3:AX33) -> 266808 | AZ34: TOTALES | BA34: =SUM(BA3:BA33) -> 198543 | BB34: =SUM(BB3:BB33) -> 0 | BC34: =SUM(BC3:BC33) -> 198543 | BE34: TOTALES | BF34: =SUM(BF3:BF33) -> 0 | BG34: =SUM(BG3:BG33) -> 0 | BH34: =SUM(BH3:BH33) -> 0
AQ36: =AQ34/30 -> 5377.2 | AV36: =AV34/31 -> 8606.7097 | BA36: =BA34/25 -> 7941.72

Sheet AÑO
B2: MES | C2: INGRESOS | D2: EGRESOS | E2: TOTALES
B3: ENERO | C3: =RELACIONES!C34 -> 197993 | D3: =RELACIONES!D34 -> 83514 | E3: =C3-D3 -> 114479
B4: FEBRERO | C4: =RELACIONES!H34 -> 207830 | D4: =RELACIONES!I34 -> 81796 | E4: =C4-D4 -> 126034
B5: MARZO | C5: =RELACIONES!M34 -> 234449 | D5: =RELACIONES!N34 -> 98729 | E5: =C5-D5 -> 135720
B6: ABRIL | C6: =RELACIONES!R34 -> 178096 | D6: =RELACIONES!S34 -> 62364 | E6: =C6-D6 -> 115732
B7: MAYO | C7: =RELACIONES!W34 -> 149925 | D7: =RELACIONES!X34 -> 55384 | E7: =C7-D7 -> 94541
B8: JUNIO | C8: =RELACIONES!AB34 -> 156863 | D8: =RELACIONES!AC34 -> 66568 | E8: =C8-D8 -> 90295
B9: JULIO | C9: =RELACIONES!AG34 -> 87461 | D9: =RELACIONES!AH34 -> 41907 | E9: =C9-D9 -> 45554
B10: AGOSTO | C10: =RELACIONES!AL34 -> 0 | D10: =RELACIONES!AM34 -> 0 | E10: =C10-D10 -> 0
B11: SEPTIEMBRE | C11: =RELACIONES!AQ34 -> 161316 | D11: =RELACIONES!AR34 -> 0 | E11: =C11-D11 -> 161316
B12: OCTUBRE | C12: =RELACIONES!AV34 -> 266808 | D12: =RELACIONES!AW34 -> 0 | E12: =C12-D12 -> 266808
B13: NOVIEMBRE | C13: =RELACIONES!BA34 -> 198543 | D13: =RELACIONES!BB34 -> 0 | E13: =C13-D13 -> 198543
B14: DICIEMBRE | C14: =RELACIONES!BF34 -> 0 | D14: =RELACIONES!BG34 -> 0 | E14: =C14-D14 -> 0
B15: TOTALES | C15: =SUM(C3:C14) -> 1839284 | D15: =SUM(D3:D14) -> 490262 | E15: =C15-D15 -> 1349022

Sheet Vacaciones
A1: 2026
A2: 2026
A3: Mary | B3: Chuy | C3: Rey | D3: Lupita | E3: Clau

Sheet Mostrador
A2: articulo | B2: cantidad inicial | C2: cantidad enexistencia | D2: precio al publico
A3: alga tostada
A4: rollo alga tostada
A5: pan de frijol dulce
A6: dulce bloques
A7: pan relleno de mermelada
A8: gelatina
A9: mochi
A10: bomboness rellenos
A11: dulce de ciruela
A12: gomitas
A13: gomitas de limon
A14: galleta dulce

Sheet Horarios
A2: Mesas | B2: LUNES | C2: MARTES | D2: MIERCOLES | E2: JUEVES | F2: VIERNES | G2: SABADO | H2: DOMIGO
A3: 10am-4pm | B3: Vianney | C3: Lupita | D3: Lupita | E3: Lupita | F3: Lupita | G3: Citlalli | H3: Citlalli
A4: 4pm-10 pm | B4: Lupita | C4: Claudia | D4: lupita | E4: Claudia | F4: Claudia | G4: Claudia | H4: Claudia
A6: Cocina | B6: LUNES | C6: MARTES | D6: MIERCOLES | E6: JUEVES | F6: VIERNES | G6: SABADO | H6: DOMIGO
A7: 10am-4pm | B7: Mary | C7: Citlalli | D7: Mary | E7: Citlalli | F7: Mary | G7: Mary | H7: Mary
A8: 4pm-10 pm | B8: Chuy | C8: Mary | D8: Chuy | E8: Chuy | F8: Chuy | G8: Chuy | H8: Chuy
A10: 1:30-9:30 | B10: LUNES | C10: MARTES | D10: MIERCOLES | E10: JUEVES | F10: VIERNES | G10: SABADO | H10: DOMIGO
A11: Cocina | B11: mary | C11: chuy | D11: chuy | E11: mary | F11: mary | G11: mary | H11: mary
B12: 400 | C12: 400 | D12: 400 | E12: 400 | F12: 400 | G12: 400 | H12: 400
A13: Mesas | B13: Lupita | C13: Lupita | D13: Lupita | E13: Claudia | F13: Lupita | G13: Claudia | H13: Claudia
B14: 320 | C14: 320 | D14: 320 | E14: 320 | F14: 320 | G14: 320 | H14: 320

Sheet Sheet1
E7: Lista de importados
E8: 2 Salsa de pescado
E9: 1 Kg curry amarillo
E10: 1 lata salsa de ostion
E11: 1 lata salsa hoisin
E12: 1 Lata salsa de anguila
E13: 3 Botellas soya dulce
E14: 1 Bota Sriracha
E15: 1 Bote Sambal
E16: 1 Bote viangre de arroz
E17: 1 lata aceite ajonjoli
E18: 1 Botella sake
... E29: 2 leche de coco

Sheet Sheet2
